# C中的异常

+ 终止程序：如assert，缺陷：如果发生内存错误（除0），就会终止程序
+ 返回错误码：errno，缺陷：需要用户自己查找对应的错误
+ setjmp 和 longjmp：错误跳转，缺陷：不常用，在C++中存在对象不能被析构的问题，造成内存泄漏

```cpp
#include <iostream>
#include <setjmp.h>
jmp_buf static_buf; //用来存放处理器上下文，用于跳转

void do_jmp(){
    //do something,simetime occurs a little error
    //调用longjmp后，会载入static_buf的处理器信息，然后第二个参数作为返回点的setjmp这个函数的返回值
    longjmp(static_buf,10);//10是错误码，根据这个错误码来进行相应的处理
}

int main(){
    int ret = 0;
    //将处理器信息保存到static_buf中,并返回0，相当于在这里做了一个标记，后面可以跳转过来
    if((ret = setjmp(static_buf)) == 0) {
        //要执行的代码
        do_jmp();
    } else {    //出现了错误
        if (ret == 10)
            std::cout << "a little error" << std::endl;
    }
}
```

# C++中的异常

> throw：抛出异常
>
> catch：捕获异常
>
> try：其中的代码标识将被激活的特定异常

```cpp
try
{
   // 保护代码
}catch( ExceptionName e1 )
{
   // catch 块
}catch( ExceptionName e2 )
{
   // catch 块
}catch( ExceptionName eN )
{
   // catch 块
}
```

![1584436253323](.\1584436253323.png)

| 异常                   | 描述                                                         |
| ---------------------- | ------------------------------------------------------------ |
| **std::exception**     | 该异常是所有标准 C++ 异常的父类。                            |
| std::bad_alloc         | 该异常可以通过 **new** 抛出。                                |
| std::bad_cast          | 该异常可以通过 **dynamic_cast** 抛出。                       |
| std::bad_exception     | 这在处理 C++ 程序中无法预期的异常时非常有用。                |
| std::bad_typeid        | 该异常可以通过 **typeid** 抛出。                             |
| **std::logic_error**   | 理论上可以通过读取代码来检测到的异常。                       |
| std::domain_error      | 当使用了一个无效的数学域时，会抛出该异常。                   |
| std::invalid_argument  | 当使用了无效的参数时，会抛出该异常。                         |
| std::length_error      | 当创建了太长的 std::string 时，会抛出该异常。                |
| std::out_of_range      | 该异常可以通过方法抛出，例如 std::vector 和 std::bitset<>::operator[]()。 |
| **std::runtime_error** | 理论上不可以通过读取代码来检测到的异常。                     |
| std::overflow_error    | 当发生数学上溢时，会抛出该异常。                             |
| std::range_error       | 当尝试存储超出范围的值时，会抛出该异常。                     |
| std::underflow_error   | 当发生数学下溢时，会抛出该异常。                             |

### 定义新的异常

可以通过继承和重载exception类来定义新的异常

```cpp
#include <iostream>
#include <exception>
using namespace std;
 
struct MyException : public exception
{
  const char * what () const throw ()
  {
    return "C++ Exception";
  }
};
 
int main()
{
  try
  {
    throw MyException();
  }
  catch(MyException& e)
  {
    std::cout << "MyException caught" << std::endl;
    std::cout << e.what() << std::endl;
  }
  catch(std::exception& e)
  {
    //其他的错误
  }
}
```

